Workbook
Name 請款單月份清單: '育兒費'!$A$12:$A$62

Sheet 儀表板
A1: 💼 個人財務管理總表 ── 儀表板
B2: 最後更新日期： | C2: 2026-09-18 02:01 | D2: （例如：2026/09/03）
A4: 📊 本月收支總覽
B5: 項目 | C5: 金額 | D5: 說明
B6: 月收入合計 | C6: =收支明細!C12 | D6: 含薪資與基金預估配息
B7: 月支出合計 | C7: =收支明細!C32 | D7: 含房貸、生活費、保險等
B8: 月淨結餘 | C8: =C6+C7
A10: 🏦 資產負債總覽
B11: 項目 | C11: 金額 | D11: 說明
B12: 總資產 | C12: =資產負債表!C14 | D12: 基金市值＋不動產＋股票＋現金
B13: 總負債 | C13: =資產負債表!C26 | D13: 各項貸款餘額合計
B14: 淨值（資產－負債） | C14: =C12-C13
B15: 負債比 | C15: =C13/C12 | D15: 總負債 ÷ 總資產，越低越健康
A17: 💰 基金部位總覽
B18: 項目 | C18: 數值 | D18: 說明
B19: 總投入成本(台幣) | C19: =基金配息紀錄!G13
B20: 總持有單位數 | C20: =基金配息紀錄!H13
B21: 加權平均成本(NAV/USD) | C21: =基金配息紀錄!I13
B22: 近12個月平均年化報酬率 | C22: =基金配息紀錄!L54 | D22: 以實際配息回推之年化率
A24: ⚠️ 財務警示
B25: =IF(C8<0,"🔴 本月收支呈現赤字，請檢視支出","✅ 本月收支為正")
B26: =IF(C8<20000,"⚠️ 淨結餘緩衝空間偏低（低於2萬）","✅ 淨結餘緩衝空間尚可")
B27: =IF(C14<0,"🔴 淨值為負，資不抵債","✅ 淨值為正")
A29: 📖 使用說明 / 色彩圖例
B30: 藍字＝原始輸入資料（金額、日期、利率等事實）；黑字＝同分頁自動計算公式；綠字＝跨分頁連結公式（不要手動修改）
B31: 黃底＝關鍵假設或需要每月更新的欄位（如基金配息率、最新NAV、匯率）
B32: 「收支明細」「貸款總覽」「基金配息紀錄」「股票投資」「信用卡年支出」為明細分頁，「資產負債表」彙總淨值
B33: 每月更新建議順序：① 基金配息紀錄 新增當月配息 ② 資產負債表 更新NAV/不動產估值/貸款餘額 ③ 回到本頁確認儀表板數字
A35: 🔄 自動更新狀態
B36: 最後自動更新時間 | C36: =資產負債表!C39
B37: 資料來源 | C37: =資產負債表!C40

Sheet 資產負債表
A1: ⚖️ 資產負債表
A3: ⚙️ 市值假設（請每次更新時填寫）
B4: 基金最新淨值(NAV,USD) | C4: 73.29 | D4: 請查詢基富通/鉅亨網最新淨值
B5: 目前匯率(USD/TWD) | C5: 31.864 | D5: 請查詢即期匯率
A7: 🏦 資產（計入個人淨值）
B8: 項目 | C8: 金額 | D8: 說明
A9: 1 | B9: 基金市值 | C9: =基金配息紀錄!H13*C4*C5 | D9: ＝總單位數×最新NAV×匯率
A10: 2 | B10: 北區不動產估值 | C10: 21050000 | D10: 市場估值，全額歸屬本人
A11: 3 | B11: 東區不動產估值 | C11: 7481250 | D11: 與弟弟共有各半，此為本人份額
A12: 4 | B12: 股票市值(0050/0052/摩根新興科技基金等) | C12: 2108034 | D12: ＝0050/0052/摩根新興科技基金市值加總（每日自動更新，明細見「股票部位」分頁）
A13: 5 | B13: 現金／存款 | C13: 0 | D13: 請填入銀行帳戶餘額
A14: 總資產 | C14: =SUM(C9:C13)
A15: （備忘）家妍投資剩餘部位 | C15: =股票投資!C24 | D15: 投機性個股，屬家妍個人資產，不計入淨值
A17: 📉 負債
B18: 項目 | C18: 金額 | D18: 說明
A19: 1 | B19: 北區原房貸餘額 | C19: =貸款總覽!L5 | D19: 理論剩餘本金＝依起始日期與已繳期數攤還試算
A20: 2 | B20: 北區理財型房貸餘額 | C20: =貸款總覽!L6 | D20: 理論剩餘本金＝依起始日期與已繳期數攤還試算
A21: 3 | B21: 東區房貸餘額 | C21: =貸款總覽!L7 | D21: 理論剩餘本金＝依起始日期與已繳期數攤還試算
A22: 4 | B22: 車貸餘額 | C22: =貸款總覽!L8 | D22: 理論剩餘本金＝依起始日期與已繳期數攤還試算
A23: 5 | B23: 信貸餘額 | C23: =貸款總覽!L9 | D23: 理論剩餘本金＝依起始日期與已繳期數攤還試算
A24: 6 | B24: 北區房貸壽險剩餘保費 | C24: =貸款總覽!L14 | D24: 剩餘保費＝直線攤還法，依已繳期數遞減
A25: 7 | B25: 東區房貸壽險剩餘保費 | C25: =貸款總覽!L15 | D25: 剩餘保費＝直線攤還法，依已繳期數遞減
A26: 總負債 | C26: =SUM(C19:C25)
A28: 🧾 淨值
A29: 淨值（資產－負債） | C29: =C14-C26
A30: 負債比 | C30: =C26/C14 | D30: 總負債÷總資產
A31: 基金未實現損益(USD) | C31: =(基金配息紀錄!H13*(C4-基金配息紀錄!I13)) | D31: ＝總單位數×(最新NAV－加權平均成本)
A33: 💡 使用說明
B34: 每次更新：① 上方填入基金最新NAV與匯率 ② 填入不動產估值、股票市值、現金餘額(黃底) ③ 負債已自動引用「貸款總覽」理論剩餘本金（依起始日期與已繳期數試算）。
B35: 若「貸款總覽」尚未填起始日期，該筆負債暫以原始貸款金額計算；填入起始日期後，餘額會隨已繳期數自動遞減。
B36: 本表淨值與儀表板同步顯示，是判斷整體財務健康度的核心指標。
A38: 🔄 淨值／匯率自動更新狀態
B39: 最後自動更新時間 | C39: 2026-09-18 02:01
B40: 資料來源 | C40: MoneyDJ（基金淨值）／Frankfurter歐洲央行參考匯率(備援)（USD/TWD匯率）
B41: 更新方式 | C41: 每日自動（也可手動覆寫上方 NAV／匯率）

Sheet 淨值歷史
A1: 📈 淨值歷史（每日自動追蹤）
A2: 此分頁由「每日淨值自動更新」流程負責寫入，記錄每天的基金淨值、匯率與資產負債快照，供儀表板繪製走勢圖。你不需要手動填寫這裡。
A4: 日期 | B4: 基金NAV(USD) | C4: USD/TWD匯率 | D4: 基金市值(TWD) | E4: 總資產(TWD) | F4: 總負債(TWD) | G4: 淨值(TWD) | H4: 更新來源
A5: 46281 | B5: 73.05 | C5: 31.8 | D5: 18047755 | E5: 48579005 | F5: 25196830 | G5: 23382175 | H5: 手動（重新設計當天回填）
A6: 46282 | B6: 73.15 | C6: 31.858 | D6: 18105424 | E6: 48726508 | F6: 25196830 | G6: 23529678 | H6: MoneyDJ／Frankfurter歐洲央行參考匯率(備援)（每日自動）
A7: 46283 | B7: 73.29 | C7: 31.864 | D7: 18143492 | E7: 48782776 | F7: 25196830 | G7: 23585945 | H7: MoneyDJ／Frankfurter歐洲央行參考匯率(備援)（每日自動）

Sheet 年度總結
A1: 📅 年度總結（報稅／年度回顧用）
A3: ⚙️ 說明
B4: 本表依年度自動加總「基金配息紀錄」「育兒費」兩分頁的歷史資料，年底或報稅時可直接查閱，不需手動翻找逐月明細。
B5: 「淨值成長」目前無法自動計算：系統沒有記錄歷年年末的NAV/匯率快照，只有網頁「淨值趨勢」功能啟用後才會開始累積歷史資料，過去年度無法回溯。
B6: 「新增申購金額」以購買日期的民國年份判斷所屬年度；「育兒費支出」為本人負擔金額(教育費+醫療費+保險費)÷2。
A8: 年度總覽
A9: 年度 | B9: 該年實收配息 (TWD) | C9: 該年新增申購 (TWD) | D9: 該年育兒費支出 (本人負擔,TWD) | E9: 備註
A10: 113年 | B10: =SUMIFS(基金配息紀錄!F$20:F$51,基金配息紀錄!M$20:M$51,"113年") | C10: =SUMIFS(基金配息紀錄!F$5:F$13,基金配息紀錄!B$5:B$13,"113/*") | D10: =(SUMIFS(育兒費!$M$12:M$633,育兒費!$K$12:K$633,"113年*",育兒費!$L$12:L$633,"教育費")+SUMIFS(育兒費!$M$12:M$633,育兒費!$K$12:K$633,"113年*",育兒費!$L$12:L$633,"醫療費")+SUMIFS(育兒費!$M$12:M$633,育兒費!$K$12:K$633,"113年*",育兒費!$L$12:L$633,"保險費"))/2
A11: 114年 | B11: =SUMIFS(基金配息紀錄!F$20:F$51,基金配息紀錄!M$20:M$51,"114年") | C11: =SUMIFS(基金配息紀錄!F$5:F$13,基金配息紀錄!B$5:B$13,"114/*") | D11: =(SUMIFS(育兒費!$M$12:M$633,育兒費!$K$12:K$633,"114年*",育兒費!$L$12:L$633,"教育費")+SUMIFS(育兒費!$M$12:M$633,育兒費!$K$12:K$633,"114年*",育兒費!$L$12:L$633,"醫療費")+SUMIFS(育兒費!$M$12:M$633,育兒費!$K$12:K$633,"114年*",育兒費!$L$12:L$633,"保險費"))/2
A12: 115年 | B12: =SUMIFS(基金配息紀錄!F$20:F$51,基金配息紀錄!M$20:M$51,"115年") | C12: =SUMIFS(基金配息紀錄!F$5:F$13,基金配息紀錄!B$5:B$13,"115/*") | D12: =(SUMIFS(育兒費!$M$12:M$633,育兒費!$K$12:K$633,"115年*",育兒費!$L$12:L$633,"教育費")+SUMIFS(育兒費!$M$12:M$633,育兒費!$K$12:K$633,"115年*",育兒費!$L$12:L$633,"醫療費")+SUMIFS(育兒費!$M$12:M$633,育兒費!$K$12:K$633,"115年*",育兒費!$L$12:L$633,"保險費"))/2
A13: 116年 | B13: =SUMIFS(基金配息紀錄!F$20:F$51,基金配息紀錄!M$20:M$51,"116年") | C13: =SUMIFS(基金配息紀錄!F$5:F$13,基金配息紀錄!B$5:B$13,"116/*") | D13: =(SUMIFS(育兒費!$M$12:M$633,育兒費!$K$12:K$633,"116年*",育兒費!$L$12:L$633,"教育費")+SUMIFS(育兒費!$M$12:M$633,育兒費!$K$12:K$633,"116年*",育兒費!$L$12:L$633,"醫療費")+SUMIFS(育兒費!$M$12:M$633,育兒費!$K$12:K$633,"116年*",育兒費!$L$12:L$633,"保險費"))/2
A14: 117年 | B14: =SUMIFS(基金配息紀錄!F$20:F$51,基金配息紀錄!M$20:M$51,"117年") | C14: =SUMIFS(基金配息紀錄!F$5:F$13,基金配息紀錄!B$5:B$13,"117/*") | D14: =(SUMIFS(育兒費!$M$12:M$633,育兒費!$K$12:K$633,"117年*",育兒費!$L$12:L$633,"教育費")+SUMIFS(育兒費!$M$12:M$633,育兒費!$K$12:K$633,"117年*",育兒費!$L$12:L$633,"醫療費")+SUMIFS(育兒費!$M$12:M$633,育兒費!$K$12:K$633,"117年*",育兒費!$L$12:L$633,"保險費"))/2
A15: 合計 | B15: =SUM(B10:B14) | C15: =SUM(C10:C14) | D15: =SUM(D10:D14)

Sheet 股票部位
A1: 📊 股票／基金部位（本人）
A2: 本人持有的0050/0052/摩根新興科技證券投資信託基金部位，市值＝持有數量×最新價格，與「股票投資」分頁（家妍個人投機部位，僅計成本）分開追蹤，會計入個人淨值。0050/0052收盤價與摩根新興科技基金淨值每日自動更新（來源：證交所TWSE／MoneyDJ）。
A4: 代號 | B4: 名稱 | C4: 持有數量 | D4: 均價／申購淨值 | E4: 最新價格／淨值 | F4: 市值 | G4: 未實現損益 | H4: 價格日期 | I4: 資料來源
A5: 0050 | B5: 元大台灣50 | C5: 8000 | D5: 64.92 | E5: 108.05 | F5: 864400 | G5: 345040 | H5: 2026-09-17 | I5: 證交所（TWSE）每日收盤價（每日自動）
A6: 0052 | B6: 富邦科技 | C6: 12000 | D6: 35.66 | E6: 62.7 | F6: 752400 | G6: 324480 | H6: 2026-09-17 | I6: 證交所（TWSE）每日收盤價（每日自動）
A7: 摩根新興科技證券投資信託基金 | B7: 摩根新興科技基金-一般型 | C7: 1091 | D7: 485.79 | E7: 450.26 | F7: 491234 | G7: -38763 | H7: 2026-09-17 | I7: MoneyDJ 基金淨值（每日自動）
B8: 小計 | F8: =SUM(F5:F7) | G8: =SUM(G5:G7)

Sheet 基金配息紀錄
A1: 💰 摩根多重收益基金 ── 申購記錄與配息追蹤
P2: 配息基準日對照表(民國年月->基準日)
A3: 申購記錄（成本基礎自動累計，可隨時新增購買） | P3: 年月 | Q3: 基準日
A4: 批次 | B4: 購買日期 | C4: 購買點位 (NAV,USD) | D4: 申購單位數 | E4: 購買匯率 (USD/TWD) | F4: 單筆申購金額 (TWD) | G4: 基金共投入資金 (TWD,累計) | H4: 累計單位數 (輔助) | I4: 加權平均成本 (NAV,USD) | J4: 說明 | P4: 11501 | Q4: 7
A5: 1 | B5: 114/04 | C5: 71.447 | D5: 1723.533 | E5: =IF(OR(C5="",D5="",F5=""),"",F5/(C5*D5)) | F5: 4000000 | G5: =F5 | H5: =D5 | I5: =IF(H5=0,"",SUMPRODUCT($C$5:C5,$D$5:D5)/H5) | J5: 400萬初始部位 | K5: =IF(B5="","",IF(ISNUMBER(FIND("/",B5,FIND("/",B5)+1)),DATE(VALUE(LEFT(B5,FIND("/",B5)-1))+1911,VALUE(MID(B5,FIND("/",B5)+1,2)),VALUE(MID(B5,FIND("/",B5,FIND("/",B5)+1)+1,2))),DATE(VALUE(LEFT(B5,FIND("/",B5)-1))+1911,VALUE(MID(B5,FIND("/",B5)+1,2)),1))) | P5: 11502 | Q5: 9
A6: 2 | B6: 115/04/30 | C6: 74.81 | D6: 3498.549 | E6: =IF(OR(C6="",D6="",F6=""),"",F6/(C6*D6)) | F6: 8304663 | G6: =G5+F6 | H6: =H5+D6 | I6: =IF(H6=0,"",SUMPRODUCT($C$5:C6,$D$5:D6)/H6) | J6: 增貸830萬(皇普莊園轉增貸1684萬-原有854萬) | K6: =IF(B6="","",IF(ISNUMBER(FIND("/",B6,FIND("/",B6)+1)),DATE(VALUE(LEFT(B6,FIND("/",B6)-1))+1911,VALUE(MID(B6,FIND("/",B6)+1,2)),VALUE(MID(B6,FIND("/",B6,FIND("/",B6)+1)+1,2))),DATE(VALUE(LEFT(B6,FIND("/",B6)-1))+1911,VALUE(MID(B6,FIND("/",B6)+1,2)),1))) | P6: 11503 | Q6: 9
A7: 3 | B7: 115/08/25 | C7: 74.63 | D7: 6.295 | E7: =IF(OR(C7="",D7="",F7=""),"",F7/(C7*D7)) | F7: 15000 | G7: =G6+F7 | H7: =H6+D7 | I7: =IF(H7=0,"",SUMPRODUCT($C$5:C7,$D$5:D7)/H7) | J7: 自補現金1.5萬(湊600萬) | K7: =IF(B7="","",IF(ISNUMBER(FIND("/",B7,FIND("/",B7)+1)),DATE(VALUE(LEFT(B7,FIND("/",B7)-1))+1911,VALUE(MID(B7,FIND("/",B7)+1,2)),VALUE(MID(B7,FIND("/",B7,FIND("/",B7)+1)+1,2))),DATE(VALUE(LEFT(B7,FIND("/",B7)-1))+1911,VALUE(MID(B7,FIND("/",B7)+1,2)),1))) | P7: 11504 | Q7: 7
A8: 4 | B8: 115/08/27 | C8: 74.91 | D8: 2519.381 | E8: =IF(OR(C8="",D8="",F8=""),"",F8/(C8*D8)) | F8: 5985000 | G8: =G7+F8 | H8: =H7+D8 | I8: =IF(H8=0,"",SUMPRODUCT($C$5:C8,$D$5:D8)/H8) | J8: 東區房貸融資598.5萬(涉谷區原屋融貸) | K8: =IF(B8="","",IF(ISNUMBER(FIND("/",B8,FIND("/",B8)+1)),DATE(VALUE(LEFT(B8,FIND("/",B8)-1))+1911,VALUE(MID(B8,FIND("/",B8)+1,2)),VALUE(MID(B8,FIND("/",B8,FIND("/",B8)+1)+1,2))),DATE(VALUE(LEFT(B8,FIND("/",B8)-1))+1911,VALUE(MID(B8,FIND("/",B8)+1,2)),1))) | P8: 11505 | Q8: 7
A9: 5 | B9: 115/09/11 | C9: 73.56 | D9: 21.434 | E9: =IF(OR(C9="",D9="",F9=""),"",F9/(C9*D9)) | F9: 50000 | G9: =G8+F9 | H9: =H8+D9 | I9: =IF(H9=0,"",SUMPRODUCT($C$5:C9,$D$5:D9)/H9) | J9: 自有儲蓄5萬(券商已確認單位數) | K9: =IF(B9="","",IF(ISNUMBER(FIND("/",B9,FIND("/",B9)+1)),DATE(VALUE(LEFT(B9,FIND("/",B9)-1))+1911,VALUE(MID(B9,FIND("/",B9)+1,2)),VALUE(MID(B9,FIND("/",B9,FIND("/",B9)+1)+1,2))),DATE(VALUE(LEFT(B9,FIND("/",B9)-1))+1911,VALUE(MID(B9,FIND("/",B9)+1,2)),1))) | P9: 11506 | Q9: 8
A10: 6 | E10: =IF(OR(C10="",D10="",F10=""),"",F10/(C10*D10)) | G10: =G9+F10 | H10: =H9+D10 | I10: =IF(H10=0,"",SUMPRODUCT($C$5:C10,$D$5:D10)/H10) | J10: ← 新增購買後，在此列填入購買點位/單位數/金額即可 | K10: =IF(B10="","",IF(ISNUMBER(FIND("/",B10,FIND("/",B10)+1)),DATE(VALUE(LEFT(B10,FIND("/",B10)-1))+1911,VALUE(MID(B10,FIND("/",B10)+1,2)),VALUE(MID(B10,FIND("/",B10,FIND("/",B10)+1)+1,2))),DATE(VALUE(LEFT(B10,FIND("/",B10)-1))+1911,VALUE(MID(B10,FIND("/",B10)+1,2)),1))) | P10: 11507 | Q10: 7
A11: 7 | E11: =IF(OR(C11="",D11="",F11=""),"",F11/(C11*D11)) | G11: =G10+F11 | H11: =H10+D11 | I11: =IF(H11=0,"",SUMPRODUCT($C$5:C11,$D$5:D11)/H11) | J11: ← 新增購買後，在此列填入購買點位/單位數/金額即可 | K11: =IF(B11="","",IF(ISNUMBER(FIND("/",B11,FIND("/",B11)+1)),DATE(VALUE(LEFT(B11,FIND("/",B11)-1))+1911,VALUE(MID(B11,FIND("/",B11)+1,2)),VALUE(MID(B11,FIND("/",B11,FIND("/",B11)+1)+1,2))),DATE(VALUE(LEFT(B11,FIND("/",B11)-1))+1911,VALUE(MID(B11,FIND("/",B11)+1,2)),1))) | P11: 11508 | Q11: 11
A12: 8 | E12: =IF(OR(C12="",D12="",F12=""),"",F12/(C12*D12)) | G12: =G11+F12 | H12: =H11+D12 | I12: =IF(H12=0,"",SUMPRODUCT($C$5:C12,$D$5:D12)/H12) | J12: ← 新增購買後，在此列填入購買點位/單位數/金額即可 | K12: =IF(B12="","",IF(ISNUMBER(FIND("/",B12,FIND("/",B12)+1)),DATE(VALUE(LEFT(B12,FIND("/",B12)-1))+1911,VALUE(MID(B12,FIND("/",B12)+1,2)),VALUE(MID(B12,FIND("/",B12,FIND("/",B12)+1)+1,2))),DATE(VALUE(LEFT(B12,FIND("/",B12)-1))+1911,VALUE(MID(B12,FIND("/",B12)+1,2)),1))) | P12: 11509 | Q12: 8
A13: 9 | E13: =IF(OR(C13="",D13="",F13=""),"",F13/(C13*D13)) | G13: =G12+F13 | H13: =H12+D13 | I13: =IF(H13=0,"",SUMPRODUCT($C$5:C13,$D$5:D13)/H13) | J13: ← 新增購買後，在此列填入購買點位/單位數/金額即可 | K13: =IF(B13="","",IF(ISNUMBER(FIND("/",B13,FIND("/",B13)+1)),DATE(VALUE(LEFT(B13,FIND("/",B13)-1))+1911,VALUE(MID(B13,FIND("/",B13)+1,2)),VALUE(MID(B13,FIND("/",B13,FIND("/",B13)+1)+1,2))),DATE(VALUE(LEFT(B13,FIND("/",B13)-1))+1911,VALUE(MID(B13,FIND("/",B13)+1,2)),1))) | P13: 11510 | Q13: 7
P14: 11511 | Q14: 9
A15: 目前部位小結 | P15: 11512 | Q15: 7
A16: 總持有單位數 | D16: =H13 | E16: 總投入成本(TWD) | G16: =G13 | H16: 加權平均成本(NAV) | J16: =I13
A18: 月配息追蹤紀錄
A19: 年度 | B19: 月份 | C19: 每單位配息 (USD) | D19: 持有單位數 | E19: 配息(USD) =C×D | F19: 實收台幣 | G19: 隱含匯率 =F÷E | H19: 當期累計 投入(TWD) | I19: 當月年化 報酬率 | L19: 備註
A20: 114年 | B20: 5 | C20: 0.666 | D20: 1723.533 | E20: =C20*D20 | F20: 34561 | G20: =F20/E20 | H20: =G$5 | I20: =F20*12/H20 | M20: =A20
B21: 6 | C21: 0.677 | D21: 1723.533 | E21: =C21*D21 | F21: 34518 | G21: =F21/E21 | H21: =G$5 | I21: =F21*12/H21 | M21: =IF(A21<>"",A21,M20)
B22: 7 | C22: 0.683 | D22: 1723.533 | E22: =C22*D22 | F22: 34453 | G22: =F22/E22 | H22: =G$5 | I22: =F22*12/H22 | M22: =IF(A22<>"",A22,M21)
B23: 8 | C23: 0.685 | D23: 1723.533 | E23: =C23*D23 | F23: 35410 | G23: =F23/E23 | H23: =G$5 | I23: =F23*12/H23 | M23: =IF(A23<>"",A23,M22)
B24: 9 | C24: 0.688 | D24: 1723.533 | E24: =C24*D24 | F24: 35642 | G24: =F24/E24 | H24: =G$5 | I24: =F24*12/H24 | M24: =IF(A24<>"",A24,M23)
B25: 10 | C25: 0.691 | D25: 1723.533 | E25: =C25*D25 | F25: 36494 | G25: =F25/E25 | H25: =G$5 | I25: =F25*12/H25 | M25: =IF(A25<>"",A25,M24)
B26: 11 | C26: 0.684 | D26: 1723.533 | E26: =C26*D26 | F26: 36749 | G26: =F26/E26 | H26: =G$5 | I26: =F26*12/H26 | M26: =IF(A26<>"",A26,M25)
B27: 12 | C27: 0.687 | D27: 1723.533 | E27: =C27*D27 | F27: 37277 | G27: =F27/E27 | H27: =G$5 | I27: =F27*12/H27 | M27: =IF(A27<>"",A27,M26)
A28: 115年 | B28: 1 | C28: 0.691 | D28: 1723.533 | E28: =C28*D28 | F28: 37572 | G28: =F28/E28 | H28: =G$5 | I28: =F28*12/H28 | M28: =IF(A28<>"",A28,M27)
B29: 2 | C29: 0.693 | D29: 1723.533 | E29: =C29*D29 | F29: 37513 | G29: =F29/E29 | H29: =G$5 | I29: =F29*12/H29 | M29: =IF(A29<>"",A29,M28)
B30: 3 | C30: 0.68 | D30: 1723.533 | E30: =C30*D30 | F30: 37407 | G30: =F30/E30 | H30: =G$5 | I30: =F30*12/H30 | M30: =IF(A30<>"",A30,M29)
B31: 4 | C31: 0.672 | D31: 1723.533 | E31: =C31*D31 | F31: 36602 | G31: =F31/E31 | H31: =G$5 | I31: =F31*12/H31 | M31: =IF(A31<>"",A31,M30)
A32: 115年 | B32: 5 | C32: 0.696 | D32: 5222.082 | E32: =C32*D32 | F32: 114407 | G32: =F32/E32 | H32: =G$6 | I32: =F32*12/H32 | M32: =IF(A32<>"",A32,M31)
B33: 6 | C33: 0.69 | D33: 5222.082 | E33: =C33*D33 | F33: 113601 | G33: =F33/E33 | H33: =G$6 | I33: =F33*12/H33 | M33: =IF(A33<>"",A33,M32)
B34: 7 | C34: 0.693 | D34: 5222.082 | E34: =C34*D34 | F34: 116483 | G34: =F34/E34 | H34: =G$6 | I34: =F34*12/H34 | M34: =IF(A34<>"",A34,M33)
B35: 8 | C35: 0.692 | D35: 5222.082 | E35: =C35*D35 | F35: 115448 | G35: =F35/E35 | H35: =G$6 | I35: =F35*12/H35 | M35: =IF(A35<>"",A35,M34)
B36: 9 | C36: 0.685 | D36: =SUMIFS($D$5:$D$13,$K$5:$K$13,"<="&IF(ISNA(VLOOKUP((VALUE(LEFT(M36,3))*100+VALUE(B36)),$P$4:$Q$15,2,FALSE())),DATE((VALUE(LEFT(M36,3))+1911),VALUE(B36),1)-1,DATE((VALUE(LEFT(M36,3))+1911),VALUE(B36),VLOOKUP((VALUE(LEFT(M36,3))*100+VALUE(B36)),$P$4:$Q$15,2,FALSE())))) | E36: =IF(C36="","",C36*D36) | F36: 168995 | G36: =IF(OR(C36="",F36=""),"",F36/E36) | H36: =G$13 | I36: =IF(OR(C36="",F36=""),"",F36*12/H36) | L36: ← 待填入 | M36: =IF(A36<>"",A36,M35)
B37: 10 | D37: =SUMIFS($D$5:$D$13,$K$5:$K$13,"<="&IF(ISNA(VLOOKUP((VALUE(LEFT(M37,3))*100+VALUE(B37)),$P$4:$Q$15,2,FALSE())),DATE((VALUE(LEFT(M37,3))+1911),VALUE(B37),1)-1,DATE((VALUE(LEFT(M37,3))+1911),VALUE(B37),VLOOKUP((VALUE(LEFT(M37,3))*100+VALUE(B37)),$P$4:$Q$15,2,FALSE())))) | E37: =IF(C37="","",C37*D37) | G37: =IF(OR(C37="",F37=""),"",F37/E37) | H37: =G$13 | I37: =IF(OR(C37="",F37=""),"",F37*12/H37) | L37: ← 待填入 | M37: =IF(A37<>"",A37,M36)
B38: 11 | D38: =SUMIFS($D$5:$D$13,$K$5:$K$13,"<="&IF(ISNA(VLOOKUP((VALUE(LEFT(M38,3))*100+VALUE(B38)),$P$4:$Q$15,2,FALSE())),DATE((VALUE(LEFT(M38,3))+1911),VALUE(B38),1)-1,DATE((VALUE(LEFT(M38,3))+1911),VALUE(B38),VLOOKUP((VALUE(LEFT(M38,3))*100+VALUE(B38)),$P$4:$Q$15,2,FALSE())))) | E38: =IF(C38="","",C38*D38) | G38: =IF(OR(C38="",F38=""),"",F38/E38) | H38: =G$13 | I38: =IF(OR(C38="",F38=""),"",F38*12/H38) | L38: ← 待填入 | M38: =IF(A38<>"",A38,M37)
B39: 12 | D39: =SUMIFS($D$5:$D$13,$K$5:$K$13,"<="&IF(ISNA(VLOOKUP((VALUE(LEFT(M39,3))*100+VALUE(B39)),$P$4:$Q$15,2,FALSE())),DATE((VALUE(LEFT(M39,3))+1911),VALUE(B39),1)-1,DATE((VALUE(LEFT(M39,3))+1911),VALUE(B39),VLOOKUP((VALUE(LEFT(M39,3))*100+VALUE(B39)),$P$4:$Q$15,2,FALSE())))) | E39: =IF(C39="","",C39*D39) | G39: =IF(OR(C39="",F39=""),"",F39/E39) | H39: =G$13 | I39: =IF(OR(C39="",F39=""),"",F39*12/H39) | L39: ← 待填入 | M39: =IF(A39<>"",A39,M38)
A40: 116年 | B40: 1 | D40: =SUMIFS($D$5:$D$13,$K$5:$K$13,"<="&IF(ISNA(VLOOKUP((VALUE(LEFT(M40,3))*100+VALUE(B40)),$P$4:$Q$15,2,FALSE())),DATE((VALUE(LEFT(M40,3))+1911),VALUE(B40),1)-1,DATE((VALUE(LEFT(M40,3))+1911),VALUE(B40),VLOOKUP((VALUE(LEFT(M40,3))*100+VALUE(B40)),$P$4:$Q$15,2,FALSE())))) | E40: =IF(C40="","",C40*D40) | G40: =IF(OR(C40="",F40=""),"",F40/E40) | H40: =G$13 | I40: =IF(OR(C40="",F40=""),"",F40*12/H40) | L40: ← 待填入 | M40: =IF(A40<>"",A40,M39)
B41: 2 | D41: =SUMIFS($D$5:$D$13,$K$5:$K$13,"<="&IF(ISNA(VLOOKUP((VALUE(LEFT(M41,3))*100+VALUE(B41)),$P$4:$Q$15,2,FALSE())),DATE((VALUE(LEFT(M41,3))+1911),VALUE(B41),1)-1,DATE((VALUE(LEFT(M41,3))+1911),VALUE(B41),VLOOKUP((VALUE(LEFT(M41,3))*100+VALUE(B41)),$P$4:$Q$15,2,FALSE())))) | E41: =IF(C41="","",C41*D41) | G41: =IF(OR(C41="",F41=""),"",F41/E41) | H41: =G$13 | I41: =IF(OR(C41="",F41=""),"",F41*12/H41) | L41: ← 待填入 | M41: =IF(A41<>"",A41,M40)
...

Sheet 收支明細
A1: 📋 月度收支明細表
A3: ⚙️ 配息率假設（僅供參考，不再驅動下方收入計算）
B4: 預估年化配息率 | D4: 0.11
B5: 下方「基金配息」收入已改為抓最近3個月實際配息平均，這裡僅留作你自己評估用的參考假設
A6: 💰 收入
A7: 序 | B7: 項目 | C7: 金額 | D7: 備註
A8: 1 | B8: 月薪 | C8: 66378 | D8: 原始事實
A9: 2 | B9: 加班費 | C9: 8000 | D9: 原始事實
A10: 3 | B10: 危勞津貼 | C10: 0 | D10: 目前無，如有請填入
A11: 4 | B11: 基金配息(近3個月實際平均) | C11: =IFERROR(AVERAGE(OFFSET(基金配息紀錄!F20,MAX(0,COUNT(基金配息紀錄!F20:F51)-3),0,MIN(3,COUNT(基金配息紀錄!F20:F51)),1)),0) | D11: 取「基金配息紀錄」最近3個有資料的月份實收台幣平均，取代固定假設利率估算
A12: 收入合計 | C12: =SUM(C8:C11)
A14: 💸 支出
A15: 序 | B15: 項目 | C15: 金額 | D15: 備註
A16: 1 | B16: 【北區】原房貸 | C16: -32400 | D16: 元大銀行803萬，30年期，利率2.66%
A17: 2 | B17: 【北區】理財型房貸本利攤還 | C17: -35040 | D17: 元大銀行881萬(內含合庫房貸壽)，30年期，2.55%
A18: 3 | B18: 【北區】理財型房貸壽險 | C18: -2299 | D18: 平準型，保額800萬(20年)，保費58萬
A19: 4 | B19: 【東區】理財型房貸本利攤還 | C19: -23804 | D19: 598.5萬，30年期，2.55%
A20: 5 | B20: 【東區】理財型房貸壽險 | C20: -1651 | D20: 平準型，保額1044萬(25年)；總保費82萬9249元，與弟弟共同分攤，本人負擔41萬4625元
A21: 6 | B21: 車貸 | C21: -20892 | D21: 元大銀行140萬，6年期，利率2.35%
A22: 7 | B22: 信貸 | C22: -5718 | D22: 將來銀行20萬，36期，利率1.88%
A23: 8 | B23: 個人醫療保險費 | C23: -3300 | D23: 凱基人壽，年繳38,883，12月
A24: 9 | B24: 育兒費(本人負擔) | C24: =-育兒費!F66 | D24: 教育費＋醫療費＋保險費，與前妻各半均攤，取近12個月平均（保費實際由每月現金流支付，已併入計算）
A25: 10 | B25: 生活費 | C25: -10000 | D25: 中國信託
A26: 11 | B26: 管理費 | C26: -4100 | D26: 一坪80元＋汽車位300＋機車位100
A27: 12 | B27: 孝親費 | C27: -10000 | D27: 臺灣銀行
A28: 13 | B28: 投資(VOO/VT) | C28: -15000 | D28: VOO 12,000＋VT 3,000
A29: 14 | B29: 信用卡費 | C29: =信用卡年支出!G19 | D29: 見「信用卡年支出」分頁自動加總
A30: 15 | B30: 潘寧課輔 | C30: -10000
A31: 16 | B31: 潘維課輔 | C31: -10000
A32: 支出合計 | C32: =SUM(C16:C31)
A34: 🧾 淨結餘
A35: 月淨結餘 | C35: =C12+C32

Sheet 信用卡年支出
A1: 💳 信用卡與年度固定支出
A3: 信用卡明細（固定支出）
A4: 序 | B4: 消費項目 | C4: 玉山 | D4: 聯邦 | E4: 中信 | F4: 國泰 | G4: 台新 | H4: 備註
A5: 1 | B5: 手機電信費 | C5: -499
A6: 2 | B6: 網路費(含家用電話) | C6: -1099
A7: 3 | B7: YouTube Premium | D7: -479
A8: 4 | B8: Google one
A9: 5 | B9: Netflix | D9: -460
A10: 6 | B10: Apple music | D10: -165
A11: 7 | B11: 富士山水 | E11: -2640 | H11: 一個月4桶水
A12: 8 | B12: 酷澎 | F12: -59
A14: 信用卡明細（非固定支出）
A15: 序 | B15: 消費項目 | C15: 玉山 | D15: 聯邦 | E15: 中信 | F15: 國泰 | G15: 台新 | H15: 備註
A16: 1 | B16: 猛健樂 | G16: -3250 | H16: 12期，1150314起
A18: 各卡消費金額合計 | C18: =SUM(C5:C12)+SUM(C16:C16) | D18: =SUM(D5:D12)+SUM(D16:D16) | E18: =SUM(E5:E12)+SUM(E16:E16) | F18: =SUM(F5:F12)+SUM(F16:F16) | G18: =SUM(G5:G12)+SUM(G16:G16)
A19: 信用卡費總計 | G19: =SUM(C18:G18)
A21: 每年龐大固定支出（非月繳，需分月預留）
A22: 序 | B22: 支出項目 | C22: 金額 | D22: 繳費月份 | E22: 銀行/備註
A23: 1 | B23: 潘寧保險 | C23: 21096 | D23: 7月 | E23: 已併入「育兒費」月支出計算，此處僅供繳費月份參考，不計入右方合計
A24: 2 | B24: 潘維保險 | C24: 24888 | D24: 3月 | E24: 已併入「育兒費」月支出計算，此處僅供繳費月份參考，不計入右方合計
A25: 3 | B25: 汽車保險 | C25: 26735 | D25: 7月 | E25: 聯邦
A26: 4 | B26: 機車保險 | C26: 3189 | D26: 7月
A27: 5 | B27: 汽車牌照稅 | C27: 11230 | D27: 4月
A28: 6 | B28: 機車牌照稅 | C28: 800 | D28: 4月
A29: 7 | B29: 汽車燃料稅 | C29: 6180 | D29: 7月
A30: 8 | B30: 機車燃料稅 | C30: 600 | D30: 7月
A31: 9 | B31: 房屋稅 | D31: 5月
A32: 10 | B32: 地價稅 | D32: 7月
A33: 11 | B33: 火災地震險 | C33: 2652 | D33: 3月
A34: 12 | B34: 潘寧國小註冊費 | E34: 待填
A35: 13 | B35: 潘維幼稚園註冊費 | C35: 17100 | D35: 6月
A36: 年度固定支出合計 | C36: =SUM(C23:C35)-C23-C24 | D36: 月均攤提 | E36: =C36/12
A37: 備註：建議年終獎金先提撥12萬存入專戶，作為保險費專款專用的保留額度（獨立於左方合計數字，不隨明細增減自動調整）
A39: 💡 使用說明
B40: 「信用卡費總計」會自動連結到「收支明細」分頁的月支出；「年度固定支出」不計入月支出，屬於需另外預留的年度性支出。

Sheet 貸款總覽
A1: 🏦 貸款總覽
A3: 各項貸款明細（起始日期填寫後，已繳期數與理論剩餘本金自動試算）
A4: 序 | B4: 貸款名稱 | C4: 區域 | D4: 金融機構 | E4: 原始金額 | F4: 年利率 | G4: 期間(年) | H4: 起始日期(選填,YYYY/M/1) | I4: 已繳期數 | J4: 理論月繳(PMT) | K4: 實際月繳 | L4: 理論剩餘本金 | M4: 備註
A5: 1 | B5: 北區原房貸 | C5: 北區 | D5: 元大銀行 | E5: 8030000 | F5: 0.0266 | G5: 30 | H5: 46139 | I5: =IF(H5="","",DATEDIF(H5,TODAY(),"m")) | J5: =-PMT(F5/12,G5*12,E5) | K5: -32400 | L5: =IF(H5="",E5,E5*((1+F5/12)^(G5*12)-(1+F5/12)^I5)/((1+F5/12)^(G5*12)-1)) | M5: 803萬，30年期，利率2.66%
A6: 2 | B6: 北區理財型房貸 | C6: 北區 | D6: 元大銀行 | E6: 8810000 | F6: 0.0255 | G6: 30 | H6: 46139 | I6: =IF(H6="","",DATEDIF(H6,TODAY(),"m")) | J6: =-PMT(F6/12,G6*12,E6) | K6: -35040 | L6: =IF(H6="",E6,E6*((1+F6/12)^(G6*12)-(1+F6/12)^I6)/((1+F6/12)^(G6*12)-1)) | M6: 881萬(內含合庫房貸壽)，30年期，2.55%
A7: 3 | B7: 東區房貸 | C7: 東區 | D7: 元大銀行 | E7: 5985000 | F7: 0.0255 | G7: 30 | H7: 46261 | I7: =IF(H7="","",DATEDIF(H7,TODAY(),"m")) | J7: =-PMT(F7/12,G7*12,E7) | K7: -23804 | L7: =IF(H7="",E7,E7*((1+F7/12)^(G7*12)-(1+F7/12)^I7)/((1+F7/12)^(G7*12)-1)) | M7: 東京都涉谷區原屋融貸598.5萬
A8: 4 | B8: 車貸 | C8: - | D8: 元大銀行 | E8: 1400000 | F8: 0.0235 | G8: 6 | H8: 46233 | I8: =IF(H8="","",DATEDIF(H8,TODAY(),"m")) | J8: =-PMT(F8/12,G8*12,E8) | K8: -20892 | L8: =IF(H8="",E8,E8*((1+F8/12)^(G8*12)-(1+F8/12)^I8)/((1+F8/12)^(G8*12)-1)) | M8: 140萬，6年期，利率2.35%
A9: 5 | B9: 信貸 | C9: - | D9: 將來銀行 | E9: 200000 | F9: 0.0188 | G9: 3 | H9: 45880 | I9: =IF(H9="","",DATEDIF(H9,TODAY(),"m")) | J9: =-PMT(F9/12,G9*12,E9) | K9: -5718 | L9: =IF(H9="",E9,E9*((1+F9/12)^(G9*12)-(1+F9/12)^I9)/((1+F9/12)^(G9*12)-1)) | M9: 20萬，36期，利率1.88%，每月11號繳
A10: 合計 | E10: =SUM(E5:E9) | J10: =SUM(J5:J9) | K10: =SUM(K5:K9) | L10: =SUM(L5:L9)
A12: 壽險保費（非貸款本金，隨貸款月繳一併攤提；剩餘保費採直線攤還法）
A13: 序 | B13: 保單名稱 | C13: 區域 | D13: 保額 | E13: 保費 | F13: 期間(年) | H13: 起始日期(比照同區域房貸) | I13: 已繳期數 | K13: 月攤提 | L13: 剩餘保費(直線法) | M13: 備註
A14: 1 | B14: 北區房貸壽險 | C14: 北區 | D14: 8000000 | E14: 580000 | F14: 20 | H14: 46139 | I14: =IF(H14="","",DATEDIF(H14,TODAY(),"m")) | K14: -2299 | L14: =IF(H14="",E14,E14*MAX(0,F14*12-I14)/(F14*12)) | M14: 平準型，保障20年，保費58萬；起始日同北區理財型房貸
A15: 2 | B15: 東區房貸壽險 | C15: 東區 | D15: 10440000 | E15: 414625 | F15: 25 | H15: 46261 | I15: =IF(H15="","",DATEDIF(H15,TODAY(),"m")) | K15: -1651 | L15: =IF(H15="",E15,E15*MAX(0,F15*12-I15)/(F15*12)) | M15: 平準型，保障25年；總保費82萬9249元與弟弟共同分攤，本人負擔41萬4625元；起始日同東區房貸
A16: 壽險合計 | E16: =SUM(E14:E15) | K16: =SUM(K14:K15) | L16: =SUM(L14:L15)
A18: 📌 貸款+壽險 月繳總額（與收支明細一致）
A19: 實際月繳總額(含壽險) | K19: =K10+SUM(K14:K15)
A21: 💡 使用說明
B22: 「起始日期」欄為選填：填入後，「已繳期數」與「理論剩餘本金」會依系統日期自動更新（每月會隨還款遞減）。
B23: 「理論剩餘本金」採標準年金攤還公式計算：本金×((1+月利率)^總期數-(1+月利率)^已繳期數)/((1+月利率)^總期數-1)；未填起始日期則以原始本金為保守估計。
B24: 「理論月繳(PMT)」由利率/期間/本金公式計算，供與銀行對帳單核對；「實際月繳」為銀行實際扣款金額，用於收支計算。
B25: 本表所有貸款金額、利率、期間、起始日期皆為使用者提供之原始事實（藍字），僅總計與試算欄位（黑字/合計列）為公式計算。

Sheet 育兒費
A1: 👨‍👧‍👦 育兒費（與前妻各半均攤）
A3: ⚙️ 說明
B4: 本表分兩區：左側「月彙總」是自動加總結果，不需要手動填；右側「明細清單」才是實際輸入資料的地方。
B5: 每筆育兒相關支出（學費、教材費、安親班費、掛號費…等）都可以在右側「明細清單」新增一列，自己命名細項名稱，不受限於固定分類。
B6: 「保險費」是潘寧/潘維的醫療險保費，實際由每月現金流支付（跟教育費/醫療費一樣），已併入「本人負擔」計算，不會另外從信用卡年支出重複計算。
B7: 「本人負擔」＝(教育費＋醫療費＋保險費)÷2，這是實際會反映到「收支明細」月支出的金額。
A9: 📊 月彙總（自動計算，不需手動填） | K9: 📝 明細清單（在這裡自由新增細項）
K10: 每筆支出新增一列：年月／類別下拉選擇，金額填數字，備註自訂名稱。
A11: 年月 | B11: 教育費 | C11: 保險費 | D11: 醫療費 | E11: 費用總和 | F11: 前妻應付 (總和÷2) | G11: 本人負擔 (總和÷2) | H11: 備註 | K11: 年月 | L11: 類別 | M11: 金額 | N11: 備註
A12: 113年01月 | B12: =SUMIFS(M1:M5000,K1:K5000,A12,L1:L5000,"教育費") | C12: =SUMIFS(M1:M5000,K1:K5000,A12,L1:L5000,"保險費") | D12: =SUMIFS(M1:M5000,K1:K5000,A12,L1:L5000,"醫療費") | E12: =B12+C12+D12 | F12: =E12/2 | G12: =E12/2 | J12: =IF(COUNTIFS(K1:K5000,A12)>0,1,0) | K12: 113年01月 | L12: 教育費 | M12: 3000 | N12: 11301準公托月費(寧) | O12: =IF(K12="","",COUNTIFS($K$12:K12,K12)) | P12: =IF(K12="","",K12&"|"&O12)
A13: 113年02月 | B13: =SUMIFS(M1:M5000,K1:K5000,A13,L1:L5000,"教育費") | C13: =SUMIFS(M1:M5000,K1:K5000,A13,L1:L5000,"保險費") | D13: =SUMIFS(M1:M5000,K1:K5000,A13,L1:L5000,"醫療費") | E13: =B13+C13+D13 | F13: =E13/2 | G13: =E13/2 | J13: =IF(COUNTIFS(K1:K5000,A13)>0,1,0) | K13: 113年01月 | L13: 醫療費 | M13: 100 | N13: 1130108(維) | O13: =IF(K13="","",COUNTIFS($K$12:K13,K13)) | P13: =IF(K13="","",K13&"|"&O13)
A14: 113年03月 | B14: =SUMIFS(M1:M5000,K1:K5000,A14,L1:L5000,"教育費") | C14: =SUMIFS(M1:M5000,K1:K5000,A14,L1:L5000,"保險費") | D14: =SUMIFS(M1:M5000,K1:K5000,A14,L1:L5000,"醫療費") | E14: =B14+C14+D14 | F14: =E14/2 | G14: =E14/2 | J14: =IF(COUNTIFS(K1:K5000,A14)>0,1,0) | K14: 113年01月 | L14: 教育費 | M14: 17100 | N14: 113上學期註冊費(寧) | O14: =IF(K14="","",COUNTIFS($K$12:K14,K14)) | P14: =IF(K14="","",K14&"|"&O14)
A15: 113年04月 | B15: =SUMIFS(M1:M5000,K1:K5000,A15,L1:L5000,"教育費") | C15: =SUMIFS(M1:M5000,K1:K5000,A15,L1:L5000,"保險費") | D15: =SUMIFS(M1:M5000,K1:K5000,A15,L1:L5000,"醫療費") | E15: =B15+C15+D15 | F15: =E15/2 | G15: =E15/2 | J15: =IF(COUNTIFS(K1:K5000,A15)>0,1,0) | K15: 113年01月 | L15: 醫療費 | M15: 180 | N15: 1130110(寧) | O15: =IF(K15="","",COUNTIFS($K$12:K15,K15)) | P15: =IF(K15="","",K15&"|"&O15)
A16: 113年05月 | B16: =SUMIFS(M1:M5000,K1:K5000,A16,L1:L5000,"教育費") | C16: =SUMIFS(M1:M5000,K1:K5000,A16,L1:L5000,"保險費") | D16: =SUMIFS(M1:M5000,K1:K5000,A16,L1:L5000,"醫療費") | E16: =B16+C16+D16 | F16: =E16/2 | G16: =E16/2 | J16: =IF(COUNTIFS(K1:K5000,A16)>0,1,0) | K16: 113年01月 | L16: 教育費 | M16: 5000 | N16: 113幼稚園訂金(維) | O16: =IF(K16="","",COUNTIFS($K$12:K16,K16)) | P16: =IF(K16="","",K16&"|"&O16)
A17: 113年06月 | B17: =SUMIFS(M1:M5000,K1:K5000,A17,L1:L5000,"教育費") | C17: =SUMIFS(M1:M5000,K1:K5000,A17,L1:L5000,"保險費") | D17: =SUMIFS(M1:M5000,K1:K5000,A17,L1:L5000,"醫療費") | E17: =B17+C17+D17 | F17: =E17/2 | G17: =E17/2 | J17: =IF(COUNTIFS(K1:K5000,A17)>0,1,0) | K17: 113年01月 | L17: 醫療費 | M17: 250 | N17: 1130123(寧) | O17: =IF(K17="","",COUNTIFS($K$12:K17,K17)) | P17: =IF(K17="","",K17&"|"&O17)
A18: 113年07月 | B18: =SUMIFS(M1:M5000,K1:K5000,A18,L1:L5000,"教育費") | C18: =SUMIFS(M1:M5000,K1:K5000,A18,L1:L5000,"保險費") | D18: =SUMIFS(M1:M5000,K1:K5000,A18,L1:L5000,"醫療費") | E18: =B18+C18+D18 | F18: =E18/2 | G18: =E18/2 | J18: =IF(COUNTIFS(K1:K5000,A18)>0,1,0) | K18: 113年01月 | L18: 醫療費 | M18: 480 | N18: 1130129(維) | O18: =IF(K18="","",COUNTIFS($K$12:K18,K18)) | P18: =IF(K18="","",K18&"|"&O18)
A19: 113年08月 | B19: =SUMIFS(M1:M5000,K1:K5000,A19,L1:L5000,"教育費") | C19: =SUMIFS(M1:M5000,K1:K5000,A19,L1:L5000,"保險費") | D19: =SUMIFS(M1:M5000,K1:K5000,A19,L1:L5000,"醫療費") | E19: =B19+C19+D19 | F19: =E19/2 | G19: =E19/2 | J19: =IF(COUNTIFS(K1:K5000,A19)>0,1,0) | K19: 113年01月 | L19: 醫療費 | M19: 200 | N19: 1130131(寧) | O19: =IF(K19="","",COUNTIFS($K$12:K19,K19)) | P19: =IF(K19="","",K19&"|"&O19)
A20: 113年09月 | B20: =SUMIFS(M1:M5000,K1:K5000,A20,L1:L5000,"教育費") | C20: =SUMIFS(M1:M5000,K1:K5000,A20,L1:L5000,"保險費") | D20: =SUMIFS(M1:M5000,K1:K5000,A20,L1:L5000,"醫療費") | E20: =B20+C20+D20 | F20: =E20/2 | G20: =E20/2 | J20: =IF(COUNTIFS(K1:K5000,A20)>0,1,0) | K20: 113年02月 | L20: 教育費 | M20: 2575 | N20: 11302準公托月費(寧) | O20: =IF(K20="","",COUNTIFS($K$12:K20,K20)) | P20: =IF(K20="","",K20&"|"&O20)
A21: 113年10月 | B21: =SUMIFS(M1:M5000,K1:K5000,A21,L1:L5000,"教育費") | C21: =SUMIFS(M1:M5000,K1:K5000,A21,L1:L5000,"保險費") | D21: =SUMIFS(M1:M5000,K1:K5000,A21,L1:L5000,"醫療費") | E21: =B21+C21+D21 | F21: =E21/2 | G21: =E21/2 | J21: =IF(COUNTIFS(K1:K5000,A21)>0,1,0) | K21: 113年02月 | L21: 醫療費 | M21: 370 | N21: 1130201(維) | O21: =IF(K21="","",COUNTIFS($K$12:K21,K21)) | P21: =IF(K21="","",K21&"|"&O21)
A22: 113年11月 | B22: =SUMIFS(M1:M5000,K1:K5000,A22,L1:L5000,"教育費") | C22: =SUMIFS(M1:M5000,K1:K5000,A22,L1:L5000,"保險費") | D22: =SUMIFS(M1:M5000,K1:K5000,A22,L1:L5000,"醫療費") | E22: =B22+C22+D22 | F22: =E22/2 | G22: =E22/2 | J22: =IF(COUNTIFS(K1:K5000,A22)>0,1,0) | K22: 113年02月 | L22: 教育費 | M22: 13600 | N22: 113上學期才藝費(寧) | O22: =IF(K22="","",COUNTIFS($K$12:K22,K22)) | P22: =IF(K22="","",K22&"|"&O22)
A23: 113年12月 | B23: =SUMIFS(M1:M5000,K1:K5000,A23,L1:L5000,"教育費") | C23: =SUMIFS(M1:M5000,K1:K5000,A23,L1:L5000,"保險費") | D23: =SUMIFS(M1:M5000,K1:K5000,A23,L1:L5000,"醫療費") | E23: =B23+C23+D23 | F23: =E23/2 | G23: =E23/2 | J23: =IF(COUNTIFS(K1:K5000,A23)>0,1,0) | K23: 113年03月 | L23: 教育費 | M23: 3000 | N23: 11303準公托月費(寧) | O23: =IF(K23="","",COUNTIFS($K$12:K23,K23)) | P23: =IF(K23="","",K23&"|"&O23)
A24: 114年01月 | B24: =SUMIFS(M1:M5000,K1:K5000,A24,L1:L5000,"教育費") | C24: =SUMIFS(M1:M5000,K1:K5000,A24,L1:L5000,"保險費") | D24: =SUMIFS(M1:M5000,K1:K5000,A24,L1:L5000,"醫療費") | E24: =B24+C24+D24 | F24: =E24/2 | G24: =E24/2 | J24: =IF(COUNTIFS(K1:K5000,A24)>0,1,0) | K24: 113年03月 | L24: 保險費 | M24: 14737 | N24: 113全球人壽(維) | O24: =IF(K24="","",COUNTIFS($K$12:K24,K24)) | P24: =IF(K24="","",K24&"|"&O24)
A25: 114年02月 | B25: =SUMIFS(M1:M5000,K1:K5000,A25,L1:L5000,"教育費") | C25: =SUMIFS(M1:M5000,K1:K5000,A25,L1:L5000,"保險費") | D25: =SUMIFS(M1:M5000,K1:K5000,A25,L1:L5000,"醫療費") | E25: =B25+C25+D25 | F25: =E25/2 | G25: =E25/2 | J25: =IF(COUNTIFS(K1:K5000,A25)>0,1,0) | K25: 113年03月 | L25: 醫療費 | M25: 150 | N25: 1130304(維) | O25: =IF(K25="","",COUNTIFS($K$12:K25,K25)) | P25: =IF(K25="","",K25&"|"&O25)
A26: 114年03月 | B26: =SUMIFS(M1:M5000,K1:K5000,A26,L1:L5000,"教育費") | C26: =SUMIFS(M1:M5000,K1:K5000,A26,L1:L5000,"保險費") | D26: =SUMIFS(M1:M5000,K1:K5000,A26,L1:L5000,"醫療費") | E26: =B26+C26+D26 | F26: =E26/2 | G26: =E26/2 | J26: =IF(COUNTIFS(K1:K5000,A26)>0,1,0) | K26: 113年03月 | L26: 教育費 | M26: 3000 | N26: 甲子園畢業紀念冊(寧) | O26: =IF(K26="","",COUNTIFS($K$12:K26,K26)) | P26: =IF(K26="","",K26&"|"&O26)
A27: 114年04月 | B27: =SUMIFS(M1:M5000,K1:K5000,A27,L1:L5000,"教育費") | C27: =SUMIFS(M1:M5000,K1:K5000,A27,L1:L5000,"保險費") | D27: =SUMIFS(M1:M5000,K1:K5000,A27,L1:L5000,"醫療費") | E27: =B27+C27+D27 | F27: =E27/2 | G27: =E27/2 | J27: =IF(COUNTIFS(K1:K5000,A27)>0,1,0) | K27: 113年03月 | L27: 保險費 | M27: 1614 | N27: 113新安產險(維) | O27: =IF(K27="","",COUNTIFS($K$12:K27,K27)) | P27: =IF(K27="","",K27&"|"&O27)
A28: 114年05月 | B28: =SUMIFS(M1:M5000,K1:K5000,A28,L1:L5000,"教育費") | C28: =SUMIFS(M1:M5000,K1:K5000,A28,L1:L5000,"保險費") | D28: =SUMIFS(M1:M5000,K1:K5000,A28,L1:L5000,"醫療費") | E28: =B28+C28+D28 | F28: =E28/2 | G28: =E28/2 | J28: =IF(COUNTIFS(K1:K5000,A28)>0,1,0) | K28: 113年03月 | L28: 醫療費 | M28: 200 | N28: 1130304(寧) | O28: =IF(K28="","",COUNTIFS($K$12:K28,K28)) | P28: =IF(K28="","",K28&"|"&O28)
A29: 114年06月 | B29: =SUMIFS(M1:M5000,K1:K5000,A29,L1:L5000,"教育費") | C29: =SUMIFS(M1:M5000,K1:K5000,A29,L1:L5000,"保險費") | D29: =SUMIFS(M1:M5000,K1:K5000,A29,L1:L5000,"醫療費") | E29: =B29+C29+D29 | F29: =E29/2 | G29: =E29/2 | J29: =IF(COUNTIFS(K1:K5000,A29)>0,1,0) | K29: 113年03月 | L29: 醫療費 | M29: 50 | N29: 1130306(寧) | O29: =IF(K29="","",COUNTIFS($K$12:K29,K29)) | P29: =IF(K29="","",K29&"|"&O29)
A30: 114年07月 | B30: =SUMIFS(M1:M5000,K1:K5000,A30,L1:L5000,"教育費") | C30: =SUMIFS(M1:M5000,K1:K5000,A30,L1:L5000,"保險費") | D30: =SUMIFS(M1:M5000,K1:K5000,A30,L1:L5000,"醫療費") | E30: =B30+C30+D30 | F30: =E30/2 | G30: =E30/2 | J30: =IF(COUNTIFS(K1:K5000,A30)>0,1,0) | K30: 113年03月 | L30: 醫療費 | M30: 710 | N30: 1130306(維) | O30: =IF(K30="","",COUNTIFS($K$12:K30,K30)) | P30: =IF(K30="","",K30&"|"&O30)
A31: 114年08月 | B31: =SUMIFS(M1:M5000,K1:K5000,A31,L1:L5000,"教育費") | C31: =SUMIFS(M1:M5000,K1:K5000,A31,L1:L5000,"保險費") | D31: =SUMIFS(M1:M5000,K1:K5000,A31,L1:L5000,"醫療費") | E31: =B31+C31+D31 | F31: =E31/2 | G31: =E31/2 | J31: =IF(COUNTIFS(K1:K5000,A31)>0,1,0) | K31: 113年03月 | L31: 醫療費 | M31: 150 | N31: 1130311(維) | O31: =IF(K31="","",COUNTIFS($K$12:K31,K31)) | P31: =IF(K31="","",K31&"|"&O31)
A32: 114年09月 | B32: =SUMIFS(M1:M5000,K1:K5000,A32,L1:L5000,"教育費") | C32: =SUMIFS(M1:M5000,K1:K5000,A32,L1:L5000,"保險費") | D32: =SUMIFS(M1:M5000,K1:K5000,A32,L1:L5000,"醫療費") | E32: =B32+C32+D32 | F32: =E32/2 | G32: =E32/2 | J32: =IF(COUNTIFS(K1:K5000,A32)>0,1,0) | K32: 113年03月 | L32: 醫療費 | M32: 180 | N32: 1130320(寧) | O32: =IF(K32="","",COUNTIFS($K$12:K32,K32)) | P32: =IF(K32="","",K32&"|"&O32)
A33: 114年10月 | B33: =SUMIFS(M1:M5000,K1:K5000,A33,L1:L5000,"教育費") | C33: =SUMIFS(M1:M5000,K1:K5000,A33,L1:L5000,"保險費") | D33: =SUMIFS(M1:M5000,K1:K5000,A33,L1:L5000,"醫療費") | E33: =B33+C33+D33 | F33: =E33/2 | G33: =E33/2 | J33: =IF(COUNTIFS(K1:K5000,A33)>0,1,0) | K33: 113年03月 | L33: 醫療費 | M33: 200 | N33: 1130320(寧) | O33: =IF(K33="","",COUNTIFS($K$12:K33,K33)) | P33: =IF(K33="","",K33&"|"&O33)
A34: 114年11月 | B34: =SUMIFS(M1:M5000,K1:K5000,A34,L1:L5000,"教育費") | C34: =SUMIFS(M1:M5000,K1:K5000,A34,L1:L5000,"保險費") | D34: =SUMIFS(M1:M5000,K1:K5000,A34,L1:L5000,"醫療費") | E34: =B34+C34+D34 | F34: =E34/2 | G34: =E34/2 | J34: =IF(COUNTIFS(K1:K5000,A34)>0,1,0) | K34: 113年04月 | L34: 教育費 | M34: 3000 | N34: 11304準公托月費(寧) | O34: =IF(K34="","",COUNTIFS($K$12:K34,K34)) | P34: =IF(K34="","",K34&"|"&O34)
A35: 114年12月 | B35: =SUMIFS(M1:M5000,K1:K5000,A35,L1:L5000,"教育費") | C35: =SUMIFS(M1:M5000,K1:K5000,A35,L1:L5000,"保險費") | D35: =SUMIFS(M1:M5000,K1:K5000,A35,L1:L5000,"醫療費") | E35: =B35+C35+D35 | F35: =E35/2 | G35: =E35/2 | J35: =IF(COUNTIFS(K1:K5000,A35)>0,1,0) | K35: 113年04月 | L35: 保險費 | M35: 8537 | N35: 113台灣人壽(維) | O35: =IF(K35="","",COUNTIFS($K$12:K35,K35)) | P35: =IF(K35="","",K35&"|"&O35)
A36: 115年01月 | B36: =SUMIFS(M1:M5000,K1:K5000,A36,L1:L5000,"教育費") | C36: =SUMIFS(M1:M5000,K1:K5000,A36,L1:L5000,"保險費") | D36: =SUMIFS(M1:M5000,K1:K5000,A36,L1:L5000,"醫療費") | E36: =B36+C36+D36 | F36: =E36/2 | G36: =E36/2 | J36: =IF(COUNTIFS(K1:K5000,A36)>0,1,0) | K36: 113年04月 | L36: 醫療費 | M36: 150 | N36: 1130416(維) | O36: =IF(K36="","",COUNTIFS($K$12:K36,K36)) | P36: =IF(K36="","",K36&"|"&O36)
A37: 115年02月 | B37: =SUMIFS(M1:M5000,K1:K5000,A37,L1:L5000,"教育費") | C37: =SUMIFS(M1:M5000,K1:K5000,A37,L1:L5000,"保險費") | D37: =SUMIFS(M1:M5000,K1:K5000,A37,L1:L5000,"醫療費") | E37: =B37+C37+D37 | F37: =E37/2 | G37: =E37/2 | J37: =IF(COUNTIFS(K1:K5000,A37)>0,1,0) | K37: 113年04月 | L37: 教育費 | M37: 2000 | N37: 11308小一先修(寧) | O37: =IF(K37="","",COUNTIFS($K$12:K37,K37)) | P37: =IF(K37="","",K37&"|"&O37)
A38: 115年03月 | B38: =SUMIFS(M1:M5000,K1:K5000,A38,L1:L5000,"教育費") | C38: =SUMIFS(M1:M5000,K1:K5000,A38,L1:L5000,"保險費") | D38: =SUMIFS(M1:M5000,K1:K5000,A38,L1:L5000,"醫療費") | E38: =B38+C38+D38 | F38: =E38/2 | G38: =E38/2 | J38: =IF(COUNTIFS(K1:K5000,A38)>0,1,0) | K38: 113年04月 | L38: 教育費 | M38: 1000 | N38: 11309安親班訂金(寧) | O38: =IF(K38="","",COUNTIFS($K$12:K38,K38)) | P38: =IF(K38="","",K38&"|"&O38)
A39: 115年04月 | B39: =SUMIFS(M1:M5000,K1:K5000,A39,L1:L5000,"教育費") | C39: =SUMIFS(M1:M5000,K1:K5000,A39,L1:L5000,"保險費") | D39: =SUMIFS(M1:M5000,K1:K5000,A39,L1:L5000,"醫療費") | E39: =B39+C39+D39 | F39: =E39/2 | G39: =E39/2 | J39: =IF(COUNTIFS(K1:K5000,A39)>0,1,0) | K39: 113年05月 | L39: 教育費 | M39: 3000 | N39: 11305準公托月費(寧) | O39: =IF(K39="","",COUNTIFS($K$12:K39,K39)) | P39: =IF(K39="","",K39&"|"&O39)
A40: 115年05月 | B40: =SUMIFS(M1:M5000,K1:K5000,A40,L1:L5000,"教育費") | C40: =SUMIFS(M1:M5000,K1:K5000,A40,L1:L5000,"保險費") | D40: =SUMIFS(M1:M5000,K1:K5000,A40,L1:L5000,"醫療費") | E40: =B40+C40+D40 | F40: =E40/2 | G40: =E40/2 | J40: =IF(COUNTIFS(K1:K5000,A40)>0,1,0) | K40: 113年05月 | L40: 醫療費 | M40: 150 | N40: 1130506(維) | O40: =IF(K40="","",COUNTIFS($K$12:K40,K40)) | P40: =IF(K40="","",K40&"|"&O40)
A41: 115年06月 | B41: =SUMIFS(M1:M5000,K1:K5000,A41,L1:L5000,"教育費") | C41: =SUMIFS(M1:M5000,K1:K5000,A41,L1:L5000,"保險費") | D41: =SUMIFS(M1:M5000,K1:K5000,A41,L1:L5000,"醫療費") | E41: =B41+C41+D41 | F41: =E41/2 | G41: =E41/2 | J41: =IF(COUNTIFS(K1:K5000,A41)>0,1,0) | K41: 113年05月 | L41: 醫療費 | M41: 150 | N41: 1130513(維) | O41: =IF(K41="","",COUNTIFS($K$12:K41,K41)) | P41: =IF(K41="","",K41&"|"&O41)
A42: 115年07月 | B42: =SUMIFS(M1:M5000,K1:K5000,A42,L1:L5000,"教育費") | C42: =SUMIFS(M1:M5000,K1:K5000,A42,L1:L5000,"保險費") | D42: =SUMIFS(M1:M5000,K1:K5000,A42,L1:L5000,"醫療費") | E42: =B42+C42+D42 | F42: =E42/2 | G42: =E42/2 | J42: =IF(COUNTIFS(K1:K5000,A42)>0,1,0) | K42: 113年05月 | L42: 醫療費 | M42: 610 | N42: 1130516(寧) | O42: =IF(K42="","",COUNTIFS($K$12:K42,K42)) | P42: =IF(K42="","",K42&"|"&O42)
...

Sheet 請款單
A1: 🧾 育兒費請款單
A3: 請款月份（可從下拉選單改選其他月份）
A4: =TEXT(YEAR(EDATE(TODAY(),-1))-1911,"0")&"年"&TEXT(MONTH(EDATE(TODAY(),-1)),"00")&"月"
A6: 開立日期
A7: =TEXT(TODAY(),"yyyy/mm/dd")
A9: 費用明細
A10: 序 | B10: 類別 | C10: 金額 | D10: 備註
A11: =IF(B11="","",1) | B11: =IFERROR(INDEX(育兒費!$L$12:$L$633,MATCH(A4&"|"&1,育兒費!$P$12:$P$633,0)),"") | C11: =IFERROR(INDEX(育兒費!$M$12:$M$633,MATCH(A4&"|"&1,育兒費!$P$12:$P$633,0)),"") | D11: =IFERROR(INDEX(育兒費!$N$12:$N$633,MATCH(A4&"|"&1,育兒費!$P$12:$P$633,0)),"")
A12: =IF(B12="","",2) | B12: =IFERROR(INDEX(育兒費!$L$12:$L$633,MATCH(A4&"|"&2,育兒費!$P$12:$P$633,0)),"") | C12: =IFERROR(INDEX(育兒費!$M$12:$M$633,MATCH(A4&"|"&2,育兒費!$P$12:$P$633,0)),"") | D12: =IFERROR(INDEX(育兒費!$N$12:$N$633,MATCH(A4&"|"&2,育兒費!$P$12:$P$633,0)),"")
A13: =IF(B13="","",3) | B13: =IFERROR(INDEX(育兒費!$L$12:$L$633,MATCH(A4&"|"&3,育兒費!$P$12:$P$633,0)),"") | C13: =IFERROR(INDEX(育兒費!$M$12:$M$633,MATCH(A4&"|"&3,育兒費!$P$12:$P$633,0)),"") | D13: =IFERROR(INDEX(育兒費!$N$12:$N$633,MATCH(A4&"|"&3,育兒費!$P$12:$P$633,0)),"")
A14: =IF(B14="","",4) | B14: =IFERROR(INDEX(育兒費!$L$12:$L$633,MATCH(A4&"|"&4,育兒費!$P$12:$P$633,0)),"") | C14: =IFERROR(INDEX(育兒費!$M$12:$M$633,MATCH(A4&"|"&4,育兒費!$P$12:$P$633,0)),"") | D14: =IFERROR(INDEX(育兒費!$N$12:$N$633,MATCH(A4&"|"&4,育兒費!$P$12:$P$633,0)),"")
A15: =IF(B15="","",5) | B15: =IFERROR(INDEX(育兒費!$L$12:$L$633,MATCH(A4&"|"&5,育兒費!$P$12:$P$633,0)),"") | C15: =IFERROR(INDEX(育兒費!$M$12:$M$633,MATCH(A4&"|"&5,育兒費!$P$12:$P$633,0)),"") | D15: =IFERROR(INDEX(育兒費!$N$12:$N$633,MATCH(A4&"|"&5,育兒費!$P$12:$P$633,0)),"")
A16: =IF(B16="","",6) | B16: =IFERROR(INDEX(育兒費!$L$12:$L$633,MATCH(A4&"|"&6,育兒費!$P$12:$P$633,0)),"") | C16: =IFERROR(INDEX(育兒費!$M$12:$M$633,MATCH(A4&"|"&6,育兒費!$P$12:$P$633,0)),"") | D16: =IFERROR(INDEX(育兒費!$N$12:$N$633,MATCH(A4&"|"&6,育兒費!$P$12:$P$633,0)),"")
A17: =IF(B17="","",7) | B17: =IFERROR(INDEX(育兒費!$L$12:$L$633,MATCH(A4&"|"&7,育兒費!$P$12:$P$633,0)),"") | C17: =IFERROR(INDEX(育兒費!$M$12:$M$633,MATCH(A4&"|"&7,育兒費!$P$12:$P$633,0)),"") | D17: =IFERROR(INDEX(育兒費!$N$12:$N$633,MATCH(A4&"|"&7,育兒費!$P$12:$P$633,0)),"")
A18: =IF(B18="","",8) | B18: =IFERROR(INDEX(育兒費!$L$12:$L$633,MATCH(A4&"|"&8,育兒費!$P$12:$P$633,0)),"") | C18: =IFERROR(INDEX(育兒費!$M$12:$M$633,MATCH(A4&"|"&8,育兒費!$P$12:$P$633,0)),"") | D18: =IFERROR(INDEX(育兒費!$N$12:$N$633,MATCH(A4&"|"&8,育兒費!$P$12:$P$633,0)),"")
A19: =IF(B19="","",9) | B19: =IFERROR(INDEX(育兒費!$L$12:$L$633,MATCH(A4&"|"&9,育兒費!$P$12:$P$633,0)),"") | C19: =IFERROR(INDEX(育兒費!$M$12:$M$633,MATCH(A4&"|"&9,育兒費!$P$12:$P$633,0)),"") | D19: =IFERROR(INDEX(育兒費!$N$12:$N$633,MATCH(A4&"|"&9,育兒費!$P$12:$P$633,0)),"")
A20: =IF(B20="","",10) | B20: =IFERROR(INDEX(育兒費!$L$12:$L$633,MATCH(A4&"|"&10,育兒費!$P$12:$P$633,0)),"") | C20: =IFERROR(INDEX(育兒費!$M$12:$M$633,MATCH(A4&"|"&10,育兒費!$P$12:$P$633,0)),"") | D20: =IFERROR(INDEX(育兒費!$N$12:$N$633,MATCH(A4&"|"&10,育兒費!$P$12:$P$633,0)),"")
A21: =IF(B21="","",11) | B21: =IFERROR(INDEX(育兒費!$L$12:$L$633,MATCH(A4&"|"&11,育兒費!$P$12:$P$633,0)),"") | C21: =IFERROR(INDEX(育兒費!$M$12:$M$633,MATCH(A4&"|"&11,育兒費!$P$12:$P$633,0)),"") | D21: =IFERROR(INDEX(育兒費!$N$12:$N$633,MATCH(A4&"|"&11,育兒費!$P$12:$P$633,0)),"")
A22: =IF(B22="","",12) | B22: =IFERROR(INDEX(育兒費!$L$12:$L$633,MATCH(A4&"|"&12,育兒費!$P$12:$P$633,0)),"") | C22: =IFERROR(INDEX(育兒費!$M$12:$M$633,MATCH(A4&"|"&12,育兒費!$P$12:$P$633,0)),"") | D22: =IFERROR(INDEX(育兒費!$N$12:$N$633,MATCH(A4&"|"&12,育兒費!$P$12:$P$633,0)),"")
A23: =IF(B23="","",13) | B23: =IFERROR(INDEX(育兒費!$L$12:$L$633,MATCH(A4&"|"&13,育兒費!$P$12:$P$633,0)),"") | C23: =IFERROR(INDEX(育兒費!$M$12:$M$633,MATCH(A4&"|"&13,育兒費!$P$12:$P$633,0)),"") | D23: =IFERROR(INDEX(育兒費!$N$12:$N$633,MATCH(A4&"|"&13,育兒費!$P$12:$P$633,0)),"")
A24: =IF(B24="","",14) | B24: =IFERROR(INDEX(育兒費!$L$12:$L$633,MATCH(A4&"|"&14,育兒費!$P$12:$P$633,0)),"") | C24: =IFERROR(INDEX(育兒費!$M$12:$M$633,MATCH(A4&"|"&14,育兒費!$P$12:$P$633,0)),"") | D24: =IFERROR(INDEX(育兒費!$N$12:$N$633,MATCH(A4&"|"&14,育兒費!$P$12:$P$633,0)),"")
A25: =IF(B25="","",15) | B25: =IFERROR(INDEX(育兒費!$L$12:$L$633,MATCH(A4&"|"&15,育兒費!$P$12:$P$633,0)),"") | C25: =IFERROR(INDEX(育兒費!$M$12:$M$633,MATCH(A4&"|"&15,育兒費!$P$12:$P$633,0)),"") | D25: =IFERROR(INDEX(育兒費!$N$12:$N$633,MATCH(A4&"|"&15,育兒費!$P$12:$P$633,0)),"")
A26: =IF(B26="","",16) | B26: =IFERROR(INDEX(育兒費!$L$12:$L$633,MATCH(A4&"|"&16,育兒費!$P$12:$P$633,0)),"") | C26: =IFERROR(INDEX(育兒費!$M$12:$M$633,MATCH(A4&"|"&16,育兒費!$P$12:$P$633,0)),"") | D26: =IFERROR(INDEX(育兒費!$N$12:$N$633,MATCH(A4&"|"&16,育兒費!$P$12:$P$633,0)),"")
A27: =IF(B27="","",17) | B27: =IFERROR(INDEX(育兒費!$L$12:$L$633,MATCH(A4&"|"&17,育兒費!$P$12:$P$633,0)),"") | C27: =IFERROR(INDEX(育兒費!$M$12:$M$633,MATCH(A4&"|"&17,育兒費!$P$12:$P$633,0)),"") | D27: =IFERROR(INDEX(育兒費!$N$12:$N$633,MATCH(A4&"|"&17,育兒費!$P$12:$P$633,0)),"")
A28: =IF(B28="","",18) | B28: =IFERROR(INDEX(育兒費!$L$12:$L$633,MATCH(A4&"|"&18,育兒費!$P$12:$P$633,0)),"") | C28: =IFERROR(INDEX(育兒費!$M$12:$M$633,MATCH(A4&"|"&18,育兒費!$P$12:$P$633,0)),"") | D28: =IFERROR(INDEX(育兒費!$N$12:$N$633,MATCH(A4&"|"&18,育兒費!$P$12:$P$633,0)),"")
A30: 金額彙總
A31: 教育費 | D31: =IFERROR(INDEX(育兒費!$B$12:$B$62,MATCH(A4,育兒費!$A$12:$A$62,0)),0)
A32: 保險費 | D32: =IFERROR(INDEX(育兒費!$C$12:$C$62,MATCH(A4,育兒費!$A$12:$A$62,0)),0)
A33: 醫療費 | D33: =IFERROR(INDEX(育兒費!$D$12:$D$62,MATCH(A4,育兒費!$A$12:$A$62,0)),0)
A34: 費用總和 | D34: =IFERROR(INDEX(育兒費!$E$12:$E$62,MATCH(A4,育兒費!$A$12:$A$62,0)),0)
A36: 💰 應付金額（各半均攤）
A37: ="本月應付金額：$"&TEXT(D34/2,"#,##0")&" 元"
A39: 💡 使用方式：在最上方選擇要請款的月份（預設自動抓上個月），下面所有明細與金額會自動帶出，確認無誤後直接「列印」或「另存為PDF」寄給對方即可。此表格不會影響其他分頁的任何計算。

Sheet 股票投資
A1: 📈 股票投資紀錄（家妍投資）
A3: 買入記錄
A4: 序 | B4: 日期 | C4: 台幣收入 | D4: 美金轉匯 | E4: 實際支出 | F4: 標的 | G4: 股數 | H4: 價格 | I4: 證券商
A5: 1 | B5: 1141001 | C5: 15000 | E5: 15000 | F5: 00989A | G5: 1000 | H5: 15 | I5: 永豐金
A6: 2 | B6: 1141009 | C6: 200500 | D6: 6551.22 | E6: 6335.59 | F6: OKLO | G6: 22 | H6: 139.2 | I6: 永豐金
A7: 3 | F7: NLR | G7: 22 | H7: 148.35 | I7: 永豐金
A8: 4 | B8: 1141104 | C8: 100000 | D8: 3229.35 | E8: 3337 | F8: OKLO | G8: 28 | H8: 119 | I8: 永豐金
A9: 5 | B9: 1141114 | C9: 50000 | D9: 1602 | E9: 1624.57 | F9: NLR | G9: 13 | H9: 124.78 | I9: 永豐金
A10: 6 | B10: 1141118 | C10: 50000 | D10: 1600.51 | E10: 1677.56 | F10: OKLO | G10: 17 | H10: 98.68 | I10: 永豐金
A11: 7 | B11: 1150203 | C11: 50000 | D11: 1580.78 | E11: 1650 | F11: OKLO | G11: 22 | H11: 75 | I11: 永豐金
A12: 8 | B12: 1150519 | C12: 5507 | E12: 5507 | F12: 00989A | G12: 100 | H12: 55 | I12: 永豐金
A13: 9 | B13: 1150624 | C13: 1800 | E13: 1752 | F13: 00989A | G13: 2 | H13: 875 | I13: 永豐金
A14: 共投入金額(台幣) | C14: =SUM(C5:C13)
A16: 賣出記錄
A17: 序 | B17: 日期 | C17: 台幣轉匯 | D17: 美金轉匯 | E17: 實際收入 | F17: 標的 | G17: 股數 | H17: 價格 | I17: 證券商
A18: 1 | B18: 1150525 | C18: 17697 | E18: 17697 | F18: 00989A | G18: 1000 | H18: 17.74 | I18: 永豐金
A19: 2 | B19: 1150528 | C19: 147196 | D19: 4682.84 | F19: OKLO | G19: 67 | H19: 70 | I19: 永豐金
A20: 3 | B20: 1150724 | C20: 11600 | E20: 11600 | F20: NLR | G20: 100 | H20: 116.5 | I20: 永豐金
A21: 共收入金額(台幣) | C21: =SUM(C18:C20)
A23: 小結
A24: 市場上剩餘金額 | C24: =C14-C21 | D24: ＝共投入金額－共收入金額（尚未實現部位的成本估算）
A26: 💡 使用說明
B27: 本表為高風險個股投機部位（OKLO、NLR核能概念股），與主要基金部位分開追蹤。日期格式為民國年月日（如1141001＝114年10月01日）。
